Workbook
Name SelectedDate: 'Schedule_Matrix'!$E$2
Name IntervalHeaders: 'Schedule_Matrix'!$H$1:$BC$1
Name ActiveActivityCodes: 'Config_Settings'!$A$2:$A$13
Name tblDailyMatrix: 'Schedule_Matrix'!$A$1:$BC$200

Sheet Config_Settings
A1: Code | B1: DisplayLabel | C1: IsActive | D1: CountsAsStaffed | E1: IsPaid | F1: Category | G1: NumericValue | H1: ColorGroup | J1: Parameter | K1: Value | M1: State | N1: MinVariance | O1: MaxVariance | P1: FillColor | Q1: FontColor
A2: OWD | B2: On Work Duty | C2: TRUE | D2: TRUE | E2: TRUE | F2: Productive | G2: 1 | H2: Productive | J2: IntervalMinutes | K2: 30 | M2: Under | O2: -1 | P2: F8696B | Q2: FFFFFF
A3: OT | B3: Overtime | C3: TRUE | D3: TRUE | E3: TRUE | F3: Productive | G3: 1 | H3: Productive | J3: IntervalsPerDay | K3: 48 | M3: Exact | N3: 0 | O3: 0 | P3: 63BE7B | Q3: FFFFFF
A4: Brk | B4: Break | C4: TRUE | D4: FALSE | E4: TRUE | F4: Break | G4: 0 | H4: Nonproductive | J4: DayStartTime | K4: 0 | M4: Over | N4: 1 | P4: 5B9BD5 | Q4: FFFFFF
A5: Lch | B5: Lunch | C5: TRUE | D5: FALSE | E5: FALSE | F5: Meal | G5: 0 | H5: Nonproductive | J5: ToleranceHeadcount | K5: 0 | M5: Invalid | P5: FFC000 | Q5: 000000
A6: Mt | B6: Meeting | C6: TRUE | D6: FALSE | E6: TRUE | F6: Meeting | G6: 0 | H6: Nonproductive | J6: WorkbookEngineVersion | K6: 1.0.0-phase1 | M6: MissingRequirement | P6: BFBFBF | Q6: 000000
A7: Trn | B7: Training | C7: TRUE | D7: FALSE | E7: TRUE | F7: Training | G7: 0 | H7: Nonproductive | J7: TemplateSchemaVersion | K7: 1.0.0 | M7: Nonproductive | P7: F4B183 | Q7: 000000
A8: PTO | B8: Paid Time Off | C8: TRUE | D8: FALSE | E8: TRUE | F8: Absence | G8: 0 | H8: Inactive | J8: FormulaSetVersion | K8: 1.0.0
A9: Sick | B9: Sick Leave | C9: TRUE | D9: FALSE | E9: TRUE | F9: Absence | G9: 0 | H9: Inactive | J9: DataSnapshotID | K9: sample-2026-06-11
A10: Off | B10: Off | C10: TRUE | D10: FALSE | E10: FALSE | F10: Off | G10: 0 | H10: Inactive
A11: UA | B11: Unapproved Absence | C11: TRUE | D11: FALSE | E11: FALSE | F11: Absence | G11: 0 | H11: Inactive
A12: AL | B12: Annual Leave | C12: TRUE | D12: FALSE | E12: TRUE | F12: Absence | G12: 0 | H12: Inactive
A13: SL | B13: Sick Leave Short Code | C13: TRUE | D13: FALSE | E13: TRUE | F13: Absence | G13: 0 | H13: Inactive

Sheet Staffing_Requirements
A1: OperationalDate | B1: IntervalStart | C1: RequiredHeadcount
A2: 46184 | B2: 0 | C2: 2
A3: 46184 | B3: 0.020833333 | C3: 2
A4: 46184 | B4: 0.041666667 | C4: 2
A5: 46184 | B5: 0.0625 | C5: 2
A6: 46184 | B6: 0.083333333 | C6: 2
A7: 46184 | B7: 0.10416667 | C7: 2
A8: 46184 | B8: 0.125 | C8: 2
A9: 46184 | B9: 0.14583333 | C9: 2
A10: 46184 | B10: 0.16666667 | C10: 2
A11: 46184 | B11: 0.1875 | C11: 2
A12: 46184 | B12: 0.20833333 | C12: 2
A13: 46184 | B13: 0.22916667 | C13: 2
... A49: 46184 | B49: 0.97916667 | C49: 2

Sheet Schedule_Data
A1: EmployeeID | B1: Name | C1: OperationalDate | D1: ShiftStart | E1: ShiftEnd | F1: ActivityCode | G1: ContractualHours | H1: CurrentShift | I1: Notes | J1: ValidationState | K1: SourceRowID
A2: E001 | B2: Avery Chen | C2: 46184 | D2: 2026-06-11 08:15 | E2: 2026-06-11 17:00 | F2: OWD | G2: 8 | H2: OWD | I2: Partial first interval | J2: Valid | K2: 1
A3: E002 | B3: Blake Diaz | C3: 46184 | D3: 2026-06-11 23:45 | E3: 2026-06-12 02:15 | F3: OWD | G3: 8 | H3: OWD | I3: Overnight | J3: Valid | K3: 2
A4: E003 | B4: Casey Singh | C4: 46184 | D4: 2026-06-11 12:00 | E4: 2026-06-11 12:30 | F4: Lch | G4: 8 | H4: Lch | I4: Nonproductive | J4: Valid | K4: 3

Sheet Calc_Engine
A1: EmployeeID | B1: Name | C1: ContractualHours | D1: CurrentShift | E1: TargetDaySelect | F1: ShiftStart | G1: ShiftEnd | H1: =Schedule_Matrix!H1 | I1: =Schedule_Matrix!I1 | J1: =Schedule_Matrix!J1 | K1: =Schedule_Matrix!K1 | L1: =Schedule_Matrix!L1 | M1: =Schedule_Matrix!M1 | N1: =Schedule_Matrix!N1 | O1: =Schedule_Matrix!O1 | ... BC1: =Schedule_Matrix!BC1
A8: =Schedule_Matrix!A8 | B8: =Schedule_Matrix!B8 | C8: =Schedule_Matrix!C8 | D8: =Schedule_Matrix!D8 | E8: =Schedule_Matrix!E8 | F8: =Schedule_Matrix!F8 | G8: =Schedule_Matrix!G8 | H8: =LET(id,Schedule_Matrix!$A8,code,UPPER(TRIM(Schedule_Matrix!$D8)),rawStart,Schedule_Matrix!$F8,rawEnd,Schedule_Matrix!$G8,countsAsStaffed,IFERROR(--XLOOKUP(code,UPPER(tblActivityCodes[Code]),tblActivityCodes[CountsAsStaffed],0),0),startDT,IF(INT(rawStart)>0,rawStart,SelectedDate+MOD(rawStart,1)),endBase,IF(INT(rawEnd)>0,rawEnd,SelectedDate+MOD(rawEnd,1)),endDT,IF(endBase<=startDT,endBase+1,endBase),intervalStart,SelectedDate+Schedule_Matrix!H$1,intervalEnd,intervalStart+TIME(0,30,0),overlapDays,MAX(0,MIN(endDT,intervalEnd)-MAX(startDT,intervalStart)),IF(OR(id="",code="",rawStart="",rawEnd="",rawStart=rawEnd,countsAsStaffed=0),0,overlapDays/TIME(0,30,0))) | I8: =LET(id,Schedule_Matrix!$A8,code,UPPER(TRIM(Schedule_Matrix!$D8)),rawStart,Schedule_Matrix!$F8,rawEnd,Schedule_Matrix!$G8,countsAsStaffed,IFERROR(--XLOOKUP(code,UPPER(tblActivityCodes[Code]),tblActivityCodes[CountsAsStaffed],0),0),startDT,IF(INT(rawStart)>0,rawStart,SelectedDate+MOD(rawStart,1)),endBase,IF(INT(rawEnd)>0,rawEnd,SelectedDate+MOD(rawEnd,1)),endDT,IF(endBase<=startDT,endBase+1,endBase),intervalStart,SelectedDate+Schedule_Matrix!I$1,intervalEnd,intervalStart+TIME(0,30,0),overlapDays,MAX(0,MIN(endDT,intervalEnd)-MAX(startDT,intervalStart)),IF(OR(id="",code="",rawStart="",rawEnd="",rawStart=rawEnd,countsAsStaffed=0),0,overlapDays/TIME(0,30,0))) | J8: =LET(id,Schedule_Matrix!$A8,code,UPPER(TRIM(Schedule_Matrix!$D8)),rawStart,Schedule_Matrix!$F8,rawEnd,Schedule_Matrix!$G8,countsAsStaffed,IFERROR(--XLOOKUP(code,UPPER(tblActivityCodes[Code]),tblActivityCodes[CountsAsStaffed],0),0),startDT,IF(INT(rawStart)>0,rawStart,SelectedDate+MOD(rawStart,1)),endBase,IF(INT(rawEnd)>0,rawEnd,SelectedDate+MOD(rawEnd,1)),endDT,IF(endBase<=startDT,endBase+1,endBase),intervalStart,SelectedDate+Schedule_Matrix!J$1,intervalEnd,intervalStart+TIME(0,30,0),overlapDays,MAX(0,MIN(endDT,intervalEnd)-MAX(startDT,intervalStart)),IF(OR(id="",code="",rawStart="",rawEnd="",rawStart=rawEnd,countsAsStaffed=0),0,overlapDays/TIME(0,30,0))) | K8: =LET(id,Schedule_Matrix!$A8,code,UPPER(TRIM(Schedule_Matrix!$D8)),rawStart,Schedule_Matrix!$F8,rawEnd,Schedule_Matrix!$G8,countsAsStaffed,IFERROR(--XLOOKUP(code,UPPER(tblActivityCodes[Code]),tblActivityCodes[CountsAsStaffed],0),0),startDT,IF(INT(rawStart)>0,rawStart,SelectedDate+MOD(rawStart,1)),endBase,IF(INT(rawEnd)>0,rawEnd,SelectedDate+MOD(rawEnd,1)),endDT,IF(endBase<=startDT,endBase+1,endBase),intervalStart,SelectedDate+Schedule_Matrix!K$1,intervalEnd,intervalStart+TIME(0,30,0),overlapDays,MAX(0,MIN(endDT,intervalEnd)-MAX(startDT,intervalStart)),IF(OR(id="",code="",rawStart="",rawEnd="",rawStart=rawEnd,countsAsStaffed=0),0,overlapDays/TIME(0,30,0))) | L8: =LET(id,Schedule_Matrix!$A8,code,UPPER(TRIM(Schedule_Matrix!$D8)),rawStart,Schedule_Matrix!$F8,rawEnd,Schedule_Matrix!$G8,countsAsStaffed,IFERROR(--XLOOKUP(code,UPPER(tblActivityCodes[Code]),tblActivityCodes[CountsAsStaffed],0),0),startDT,IF(INT(rawStart)>0,rawStart,SelectedDate+MOD(rawStart,1)),endBase,IF(INT(rawEnd)>0,rawEnd,SelectedDate+MOD(rawEnd,1)),endDT,IF(endBase<=startDT,endBase+1,endBase),intervalStart,SelectedDate+Schedule_Matrix!L$1,intervalEnd,intervalStart+TIME(0,30,0),overlapDays,MAX(0,MIN(endDT,intervalEnd)-MAX(startDT,intervalStart)),IF(OR(id="",code="",rawStart="",rawEnd="",rawStart=rawEnd,countsAsStaffed=0),0,overlapDays/TIME(0,30,0))) | M8: =LET(id,Schedule_Matrix!$A8,code,UPPER(TRIM(Schedule_Matrix!$D8)),rawStart,Schedule_Matrix!$F8,rawEnd,Schedule_Matrix!$G8,countsAsStaffed,IFERROR(--XLOOKUP(code,UPPER(tblActivityCodes[Code]),tblActivityCodes[CountsAsStaffed],0),0),startDT,IF(INT(rawStart)>0,rawStart,SelectedDate+MOD(rawStart,1)),endBase,IF(INT(rawEnd)>0,rawEnd,SelectedDate+MOD(rawEnd,1)),endDT,IF(endBase<=startDT,endBase+1,endBase),intervalStart,SelectedDate+Schedule_Matrix!M$1,intervalEnd,intervalStart+TIME(0,30,0),overlapDays,MAX(0,MIN(endDT,intervalEnd)-MAX(startDT,intervalStart)),IF(OR(id="",code="",rawStart="",rawEnd="",rawStart=rawEnd,countsAsStaffed=0),0,overlapDays/TIME(0,30,0))) | N8: =LET(id,Schedule_Matrix!$A8,code,UPPER(TRIM(Schedule_Matrix!$D8)),rawStart,Schedule_Matrix!$F8,rawEnd,Schedule_Matrix!$G8,countsAsStaffed,IFERROR(--XLOOKUP(code,UPPER(tblActivityCodes[Code]),tblActivityCodes[CountsAsStaffed],0),0),startDT,IF(INT(rawStart)>0,rawStart,SelectedDate+MOD(rawStart,1)),endBase,IF(INT(rawEnd)>0,rawEnd,SelectedDate+MOD(rawEnd,1)),endDT,IF(endBase<=startDT,endBase+1,endBase),intervalStart,SelectedDate+Schedule_Matrix!N$1,intervalEnd,intervalStart+TIME(0,30,0),overlapDays,MAX(0,MIN(endDT,intervalEnd)-MAX(startDT,intervalStart)),IF(OR(id="",code="",rawStart="",rawEnd="",rawStart=rawEnd,countsAsStaffed=0),0,overlapDays/TIME(0,30,0))) | O8: =LET(id,Schedule_Matrix!$A8,code,UPPER(TRIM(Schedule_Matrix!$D8)),rawStart,Schedule_Matrix!$F8,rawEnd,Schedule_Matrix!$G8,countsAsStaffed,IFERROR(--XLOOKUP(code,UPPER(tblActivityCodes[Code]),tblActivityCodes[CountsAsStaffed],0),0),startDT,IF(INT(rawStart)>0,rawStart,SelectedDate+MOD(rawStart,1)),endBase,IF(INT(rawEnd)>0,rawEnd,SelectedDate+MOD(rawEnd,1)),endDT,IF(endBase<=startDT,endBase+1,endBase),intervalStart,SelectedDate+Schedule_Matrix!O$1,intervalEnd,intervalStart+TIME(0,30,0),overlapDays,MAX(0,MIN(endDT,intervalEnd)-MAX(startDT,intervalStart)),IF(OR(id="",code="",rawStart="",rawEnd="",rawStart=rawEnd,countsAsStaffed=0),0,overlapDays/TIME(0,30,0))) | ... BC8: =LET(id,Schedule_Matrix!$A8,code,UPPER(TRIM(Schedule_Matrix!$D8)),rawStart,Schedule_Matrix!$F8,rawEnd,Schedule_Matrix!$G8,countsAsStaffed,IFERROR(--XLOOKUP(code,UPPER(tblActivityCodes[Code]),tblActivityCodes[CountsAsStaffed],0),0),startDT,IF(INT(rawStart)>0,rawStart,SelectedDate+MOD(rawStart,1)),endBase,IF(INT(rawEnd)>0,rawEnd,SelectedDate+MOD(rawEnd,1)),endDT,IF(endBase<=startDT,endBase+1,endBase),intervalStart,SelectedDate+Schedule_Matrix!BC$1,intervalEnd,intervalStart+TIME(0,30,0),overlapDays,MAX(0,MIN(endDT,intervalEnd)-MAX(startDT,intervalStart)),IF(OR(id="",code="",rawStart="",rawEnd="",rawStart=rawEnd,countsAsStaffed=0),0,overlapDays/TIME(0,30,0)))
A9: =Schedule_Matrix!A9 | B9: =Schedule_Matrix!B9 | C9: =Schedule_Matrix!C9 | D9: =Schedule_Matrix!D9 | E9: =Schedule_Matrix!E9 | F9: =Schedule_Matrix!F9 | G9: =Schedule_Matrix!G9 | H9: =LET(id,Schedule_Matrix!$A9,code,UPPER(TRIM(Schedule_Matrix!$D9)),rawStart,Schedule_Matrix!$F9,rawEnd,Schedule_Matrix!$G9,countsAsStaffed,IFERROR(--XLOOKUP(code,UPPER(tblActivityCodes[Code]),tblActivityCodes[CountsAsStaffed],0),0),startDT,IF(INT(rawStart)>0,rawStart,SelectedDate+MOD(rawStart,1)),endBase,IF(INT(rawEnd)>0,rawEnd,SelectedDate+MOD(rawEnd,1)),endDT,IF(endBase<=startDT,endBase+1,endBase),intervalStart,SelectedDate+Schedule_Matrix!H$1,intervalEnd,intervalStart+TIME(0,30,0),overlapDays,MAX(0,MIN(endDT,intervalEnd)-MAX(startDT,intervalStart)),IF(OR(id="",code="",rawStart="",rawEnd="",rawStart=rawEnd,countsAsStaffed=0),0,overlapDays/TIME(0,30,0))) | I9: =LET(id,Schedule_Matrix!$A9,code,UPPER(TRIM(Schedule_Matrix!$D9)),rawStart,Schedule_Matrix!$F9,rawEnd,Schedule_Matrix!$G9,countsAsStaffed,IFERROR(--XLOOKUP(code,UPPER(tblActivityCodes[Code]),tblActivityCodes[CountsAsStaffed],0),0),startDT,IF(INT(rawStart)>0,rawStart,SelectedDate+MOD(rawStart,1)),endBase,IF(INT(rawEnd)>0,rawEnd,SelectedDate+MOD(rawEnd,1)),endDT,IF(endBase<=startDT,endBase+1,endBase),intervalStart,SelectedDate+Schedule_Matrix!I$1,intervalEnd,intervalStart+TIME(0,30,0),overlapDays,MAX(0,MIN(endDT,intervalEnd)-MAX(startDT,intervalStart)),IF(OR(id="",code="",rawStart="",rawEnd="",rawStart=rawEnd,countsAsStaffed=0),0,overlapDays/TIME(0,30,0))) | J9: =LET(id,Schedule_Matrix!$A9,code,UPPER(TRIM(Schedule_Matrix!$D9)),rawStart,Schedule_Matrix!$F9,rawEnd,Schedule_Matrix!$G9,countsAsStaffed,IFERROR(--XLOOKUP(code,UPPER(tblActivityCodes[Code]),tblActivityCodes[CountsAsStaffed],0),0),startDT,IF(INT(rawStart)>0,rawStart,SelectedDate+MOD(rawStart,1)),endBase,IF(INT(rawEnd)>0,rawEnd,SelectedDate+MOD(rawEnd,1)),endDT,IF(endBase<=startDT,endBase+1,endBase),intervalStart,SelectedDate+Schedule_Matrix!J$1,intervalEnd,intervalStart+TIME(0,30,0),overlapDays,MAX(0,MIN(endDT,intervalEnd)-MAX(startDT,intervalStart)),IF(OR(id="",code="",rawStart="",rawEnd="",rawStart=rawEnd,countsAsStaffed=0),0,overlapDays/TIME(0,30,0))) | K9: =LET(id,Schedule_Matrix!$A9,code,UPPER(TRIM(Schedule_Matrix!$D9)),rawStart,Schedule_Matrix!$F9,rawEnd,Schedule_Matrix!$G9,countsAsStaffed,IFERROR(--XLOOKUP(code,UPPER(tblActivityCodes[Code]),tblActivityCodes[CountsAsStaffed],0),0),startDT,IF(INT(rawStart)>0,rawStart,SelectedDate+MOD(rawStart,1)),endBase,IF(INT(rawEnd)>0,rawEnd,SelectedDate+MOD(rawEnd,1)),endDT,IF(endBase<=startDT,endBase+1,endBase),intervalStart,SelectedDate+Schedule_Matrix!K$1,intervalEnd,intervalStart+TIME(0,30,0),overlapDays,MAX(0,MIN(endDT,intervalEnd)-MAX(startDT,intervalStart)),IF(OR(id="",code="",rawStart="",rawEnd="",rawStart=rawEnd,countsAsStaffed=0),0,overlapDays/TIME(0,30,0))) | L9: =LET(id,Schedule_Matrix!$A9,code,UPPER(TRIM(Schedule_Matrix!$D9)),rawStart,Schedule_Matrix!$F9,rawEnd,Schedule_Matrix!$G9,countsAsStaffed,IFERROR(--XLOOKUP(code,UPPER(tblActivityCodes[Code]),tblActivityCodes[CountsAsStaffed],0),0),startDT,IF(INT(rawStart)>0,rawStart,SelectedDate+MOD(rawStart,1)),endBase,IF(INT(rawEnd)>0,rawEnd,SelectedDate+MOD(rawEnd,1)),endDT,IF(endBase<=startDT,endBase+1,endBase),intervalStart,SelectedDate+Schedule_Matrix!L$1,intervalEnd,intervalStart+TIME(0,30,0),overlapDays,MAX(0,MIN(endDT,intervalEnd)-MAX(startDT,intervalStart)),IF(OR(id="",code="",rawStart="",rawEnd="",rawStart=rawEnd,countsAsStaffed=0),0,overlapDays/TIME(0,30,0))) | M9: =LET(id,Schedule_Matrix!$A9,code,UPPER(TRIM(Schedule_Matrix!$D9)),rawStart,Schedule_Matrix!$F9,rawEnd,Schedule_Matrix!$G9,countsAsStaffed,IFERROR(--XLOOKUP(code,UPPER(tblActivityCodes[Code]),tblActivityCodes[CountsAsStaffed],0),0),startDT,IF(INT(rawStart)>0,rawStart,SelectedDate+MOD(rawStart,1)),endBase,IF(INT(rawEnd)>0,rawEnd,SelectedDate+MOD(rawEnd,1)),endDT,IF(endBase<=startDT,endBase+1,endBase),intervalStart,SelectedDate+Schedule_Matrix!M$1,intervalEnd,intervalStart+TIME(0,30,0),overlapDays,MAX(0,MIN(endDT,intervalEnd)-MAX(startDT,intervalStart)),IF(OR(id="",code="",rawStart="",rawEnd="",rawStart=rawEnd,countsAsStaffed=0),0,overlapDays/TIME(0,30,0))) | N9: =LET(id,Schedule_Matrix!$A9,code,UPPER(TRIM(Schedule_Matrix!$D9)),rawStart,Schedule_Matrix!$F9,rawEnd,Schedule_Matrix!$G9,countsAsStaffed,IFERROR(--XLOOKUP(code,UPPER(tblActivityCodes[Code]),tblActivityCodes[CountsAsStaffed],0),0),startDT,IF(INT(rawStart)>0,rawStart,SelectedDate+MOD(rawStart,1)),endBase,IF(INT(rawEnd)>0,rawEnd,SelectedDate+MOD(rawEnd,1)),endDT,IF(endBase<=startDT,endBase+1,endBase),intervalStart,SelectedDate+Schedule_Matrix!N$1,intervalEnd,intervalStart+TIME(0,30,0),overlapDays,MAX(0,MIN(endDT,intervalEnd)-MAX(startDT,intervalStart)),IF(OR(id="",code="",rawStart="",rawEnd="",rawStart=rawEnd,countsAsStaffed=0),0,overlapDays/TIME(0,30,0))) | O9: =LET(id,Schedule_Matrix!$A9,code,UPPER(TRIM(Schedule_Matrix!$D9)),rawStart,Schedule_Matrix!$F9,rawEnd,Schedule_Matrix!$G9,countsAsStaffed,IFERROR(--XLOOKUP(code,UPPER(tblActivityCodes[Code]),tblActivityCodes[CountsAsStaffed],0),0),startDT,IF(INT(rawStart)>0,rawStart,SelectedDate+MOD(rawStart,1)),endBase,IF(INT(rawEnd)>0,rawEnd,SelectedDate+MOD(rawEnd,1)),endDT,IF(endBase<=startDT,endBase+1,endBase),intervalStart,SelectedDate+Schedule_Matrix!O$1,intervalEnd,intervalStart+TIME(0,30,0),overlapDays,MAX(0,MIN(endDT,intervalEnd)-MAX(startDT,intervalStart)),IF(OR(id="",code="",rawStart="",rawEnd="",rawStart=rawEnd,countsAsStaffed=0),0,overlapDays/TIME(0,30,0))) | ... BC9: =LET(id,Schedule_Matrix!$A9,code,UPPER(TRIM(Schedule_Matrix!$D9)),rawStart,Schedule_Matrix!$F9,rawEnd,Schedule_Matrix!$G9,countsAsStaffed,IFERROR(--XLOOKUP(code,UPPER(tblActivityCodes[Code]),tblActivityCodes[CountsAsStaffed],0),0),startDT,IF(INT(rawStart)>0,rawStart,SelectedDate+MOD(rawStart,1)),endBase,IF(INT(rawEnd)>0,rawEnd,SelectedDate+MOD(rawEnd,1)),endDT,IF(endBase<=startDT,endBase+1,endBase),intervalStart,SelectedDate+Schedule_Matrix!BC$1,intervalEnd,intervalStart+TIME(0,30,0),overlapDays,MAX(0,MIN(endDT,intervalEnd)-MAX(startDT,intervalStart)),IF(OR(id="",code="",rawStart="",rawEnd="",rawStart=rawEnd,countsAsStaffed=0),0,overlapDays/TIME(0,30,0)))
A10: =Schedule_Matrix!A10 | B10: =Schedule_Matrix!B10 | C10: =Schedule_Matrix!C10 | D10: =Schedule_Matrix!D10 | E10: =Schedule_Matrix!E10 | F10: =Schedule_Matrix!F10 | G10: =Schedule_Matrix!G10 | H10: =LET(id,Schedule_Matrix!$A10,code,UPPER(TRIM(Schedule_Matrix!$D10)),rawStart,Schedule_Matrix!$F10,rawEnd,Schedule_Matrix!$G10,countsAsStaffed,IFERROR(--XLOOKUP(code,UPPER(tblActivityCodes[Code]),tblActivityCodes[CountsAsStaffed],0),0),startDT,IF(INT(rawStart)>0,rawStart,SelectedDate+MOD(rawStart,1)),endBase,IF(INT(rawEnd)>0,rawEnd,SelectedDate+MOD(rawEnd,1)),endDT,IF(endBase<=startDT,endBase+1,endBase),intervalStart,SelectedDate+Schedule_Matrix!H$1,intervalEnd,intervalStart+TIME(0,30,0),overlapDays,MAX(0,MIN(endDT,intervalEnd)-MAX(startDT,intervalStart)),IF(OR(id="",code="",rawStart="",rawEnd="",rawStart=rawEnd,countsAsStaffed=0),0,overlapDays/TIME(0,30,0))) | I10: =LET(id,Schedule_Matrix!$A10,code,UPPER(TRIM(Schedule_Matrix!$D10)),rawStart,Schedule_Matrix!$F10,rawEnd,Schedule_Matrix!$G10,countsAsStaffed,IFERROR(--XLOOKUP(code,UPPER(tblActivityCodes[Code]),tblActivityCodes[CountsAsStaffed],0),0),startDT,IF(INT(rawStart)>0,rawStart,SelectedDate+MOD(rawStart,1)),endBase,IF(INT(rawEnd)>0,rawEnd,SelectedDate+MOD(rawEnd,1)),endDT,IF(endBase<=startDT,endBase+1,endBase),intervalStart,SelectedDate+Schedule_Matrix!I$1,intervalEnd,intervalStart+TIME(0,30,0),overlapDays,MAX(0,MIN(endDT,intervalEnd)-MAX(startDT,intervalStart)),IF(OR(id="",code="",rawStart="",rawEnd="",rawStart=rawEnd,countsAsStaffed=0),0,overlapDays/TIME(0,30,0))) | J10: =LET(id,Schedule_Matrix!$A10,code,UPPER(TRIM(Schedule_Matrix!$D10)),rawStart,Schedule_Matrix!$F10,rawEnd,Schedule_Matrix!$G10,countsAsStaffed,IFERROR(--XLOOKUP(code,UPPER(tblActivityCodes[Code]),tblActivityCodes[CountsAsStaffed],0),0),startDT,IF(INT(rawStart)>0,rawStart,SelectedDate+MOD(rawStart,1)),endBase,IF(INT(rawEnd)>0,rawEnd,SelectedDate+MOD(rawEnd,1)),endDT,IF(endBase<=startDT,endBase+1,endBase),intervalStart,SelectedDate+Schedule_Matrix!J$1,intervalEnd,intervalStart+TIME(0,30,0),overlapDays,MAX(0,MIN(endDT,intervalEnd)-MAX(startDT,intervalStart)),IF(OR(id="",code="",rawStart="",rawEnd="",rawStart=rawEnd,countsAsStaffed=0),0,overlapDays/TIME(0,30,0))) | K10: =LET(id,Schedule_Matrix!$A10,code,UPPER(TRIM(Schedule_Matrix!$D10)),rawStart,Schedule_Matrix!$F10,rawEnd,Schedule_Matrix!$G10,countsAsStaffed,IFERROR(--XLOOKUP(code,UPPER(tblActivityCodes[Code]),tblActivityCodes[CountsAsStaffed],0),0),startDT,IF(INT(rawStart)>0,rawStart,SelectedDate+MOD(rawStart,1)),endBase,IF(INT(rawEnd)>0,rawEnd,SelectedDate+MOD(rawEnd,1)),endDT,IF(endBase<=startDT,endBase+1,endBase),intervalStart,SelectedDate+Schedule_Matrix!K$1,intervalEnd,intervalStart+TIME(0,30,0),overlapDays,MAX(0,MIN(endDT,intervalEnd)-MAX(startDT,intervalStart)),IF(OR(id="",code="",rawStart="",rawEnd="",rawStart=rawEnd,countsAsStaffed=0),0,overlapDays/TIME(0,30,0))) | L10: =LET(id,Schedule_Matrix!$A10,code,UPPER(TRIM(Schedule_Matrix!$D10)),rawStart,Schedule_Matrix!$F10,rawEnd,Schedule_Matrix!$G10,countsAsStaffed,IFERROR(--XLOOKUP(code,UPPER(tblActivityCodes[Code]),tblActivityCodes[CountsAsStaffed],0),0),startDT,IF(INT(rawStart)>0,rawStart,SelectedDate+MOD(rawStart,1)),endBase,IF(INT(rawEnd)>0,rawEnd,SelectedDate+MOD(rawEnd,1)),endDT,IF(endBase<=startDT,endBase+1,endBase),intervalStart,SelectedDate+Schedule_Matrix!L$1,intervalEnd,intervalStart+TIME(0,30,0),overlapDays,MAX(0,MIN(endDT,intervalEnd)-MAX(startDT,intervalStart)),IF(OR(id="",code="",rawStart="",rawEnd="",rawStart=rawEnd,countsAsStaffed=0),0,overlapDays/TIME(0,30,0))) | M10: =LET(id,Schedule_Matrix!$A10,code,UPPER(TRIM(Schedule_Matrix!$D10)),rawStart,Schedule_Matrix!$F10,rawEnd,Schedule_Matrix!$G10,countsAsStaffed,IFERROR(--XLOOKUP(code,UPPER(tblActivityCodes[Code]),tblActivityCodes[CountsAsStaffed],0),0),startDT,IF(INT(rawStart)>0,rawStart,SelectedDate+MOD(rawStart,1)),endBase,IF(INT(rawEnd)>0,rawEnd,SelectedDate+MOD(rawEnd,1)),endDT,IF(endBase<=startDT,endBase+1,endBase),intervalStart,SelectedDate+Schedule_Matrix!M$1,intervalEnd,intervalStart+TIME(0,30,0),overlapDays,MAX(0,MIN(endDT,intervalEnd)-MAX(startDT,intervalStart)),IF(OR(id="",code="",rawStart="",rawEnd="",rawStart=rawEnd,countsAsStaffed=0),0,overlapDays/TIME(0,30,0))) | N10: =LET(id,Schedule_Matrix!$A10,code,UPPER(TRIM(Schedule_Matrix!$D10)),rawStart,Schedule_Matrix!$F10,rawEnd,Schedule_Matrix!$G10,countsAsStaffed,IFERROR(--XLOOKUP(code,UPPER(tblActivityCodes[Code]),tblActivityCodes[CountsAsStaffed],0),0),startDT,IF(INT(rawStart)>0,rawStart,SelectedDate+MOD(rawStart,1)),endBase,IF(INT(rawEnd)>0,rawEnd,SelectedDate+MOD(rawEnd,1)),endDT,IF(endBase<=startDT,endBase+1,endBase),intervalStart,SelectedDate+Schedule_Matrix!N$1,intervalEnd,intervalStart+TIME(0,30,0),overlapDays,MAX(0,MIN(endDT,intervalEnd)-MAX(startDT,intervalStart)),IF(OR(id="",code="",rawStart="",rawEnd="",rawStart=rawEnd,countsAsStaffed=0),0,overlapDays/TIME(0,30,0))) | O10: =LET(id,Schedule_Matrix!$A10,code,UPPER(TRIM(Schedule_Matrix!$D10)),rawStart,Schedule_Matrix!$F10,rawEnd,Schedule_Matrix!$G10,countsAsStaffed,IFERROR(--XLOOKUP(code,UPPER(tblActivityCodes[Code]),tblActivityCodes[CountsAsStaffed],0),0),startDT,IF(INT(rawStart)>0,rawStart,SelectedDate+MOD(rawStart,1)),endBase,IF(INT(rawEnd)>0,rawEnd,SelectedDate+MOD(rawEnd,1)),endDT,IF(endBase<=startDT,endBase+1,endBase),intervalStart,SelectedDate+Schedule_Matrix!O$1,intervalEnd,intervalStart+TIME(0,30,0),overlapDays,MAX(0,MIN(endDT,intervalEnd)-MAX(startDT,intervalStart)),IF(OR(id="",code="",rawStart="",rawEnd="",rawStart=rawEnd,countsAsStaffed=0),0,overlapDays/TIME(0,30,0))) | ... BC10: =LET(id,Schedule_Matrix!$A10,code,UPPER(TRIM(Schedule_Matrix!$D10)),rawStart,Schedule_Matrix!$F10,rawEnd,Schedule_Matrix!$G10,countsAsStaffed,IFERROR(--XLOOKUP(code,UPPER(tblActivityCodes[Code]),tblActivityCodes[CountsAsStaffed],0),0),startDT,IF(INT(rawStart)>0,rawStart,SelectedDate+MOD(rawStart,1)),endBase,IF(INT(rawEnd)>0,rawEnd,SelectedDate+MOD(rawEnd,1)),endDT,IF(endBase<=startDT,endBase+1,endBase),intervalStart,SelectedDate+Schedule_Matrix!BC$1,intervalEnd,intervalStart+TIME(0,30,0),overlapDays,MAX(0,MIN(endDT,intervalEnd)-MAX(startDT,intervalStart)),IF(OR(id="",code="",rawStart="",rawEnd="",rawStart=rawEnd,countsAsStaffed=0),0,overlapDays/TIME(0,30,0)))
H11: =LET(id,Schedule_Matrix!$A11,code,UPPER(TRIM(Schedule_Matrix!$D11)),rawStart,Schedule_Matrix!$F11,rawEnd,Schedule_Matrix!$G11,countsAsStaffed,IFERROR(--XLOOKUP(code,UPPER(tblActivityCodes[Code]),tblActivityCodes[CountsAsStaffed],0),0),startDT,IF(INT(rawStart)>0,rawStart,SelectedDate+MOD(rawStart,1)),endBase,IF(INT(rawEnd)>0,rawEnd,SelectedDate+MOD(rawEnd,1)),endDT,IF(endBase<=startDT,endBase+1,endBase),intervalStart,SelectedDate+Schedule_Matrix!H$1,intervalEnd,intervalStart+TIME(0,30,0),overlapDays,MAX(0,MIN(endDT,intervalEnd)-MAX(startDT,intervalStart)),IF(OR(id="",code="",rawStart="",rawEnd="",rawStart=rawEnd,countsAsStaffed=0),0,overlapDays/TIME(0,30,0))) | I11: =LET(id,Schedule_Matrix!$A11,code,UPPER(TRIM(Schedule_Matrix!$D11)),rawStart,Schedule_Matrix!$F11,rawEnd,Schedule_Matrix!$G11,countsAsStaffed,IFERROR(--XLOOKUP(code,UPPER(tblActivityCodes[Code]),tblActivityCodes[CountsAsStaffed],0),0),startDT,IF(INT(rawStart)>0,rawStart,SelectedDate+MOD(rawStart,1)),endBase,IF(INT(rawEnd)>0,rawEnd,SelectedDate+MOD(rawEnd,1)),endDT,IF(endBase<=startDT,endBase+1,endBase),intervalStart,SelectedDate+Schedule_Matrix!I$1,intervalEnd,intervalStart+TIME(0,30,0),overlapDays,MAX(0,MIN(endDT,intervalEnd)-MAX(startDT,intervalStart)),IF(OR(id="",code="",rawStart="",rawEnd="",rawStart=rawEnd,countsAsStaffed=0),0,overlapDays/TIME(0,30,0))) | J11: =LET(id,Schedule_Matrix!$A11,code,UPPER(TRIM(Schedule_Matrix!$D11)),rawStart,Schedule_Matrix!$F11,rawEnd,Schedule_Matrix!$G11,countsAsStaffed,IFERROR(--XLOOKUP(code,UPPER(tblActivityCodes[Code]),tblActivityCodes[CountsAsStaffed],0),0),startDT,IF(INT(rawStart)>0,rawStart,SelectedDate+MOD(rawStart,1)),endBase,IF(INT(rawEnd)>0,rawEnd,SelectedDate+MOD(rawEnd,1)),endDT,IF(endBase<=startDT,endBase+1,endBase),intervalStart,SelectedDate+Schedule_Matrix!J$1,intervalEnd,intervalStart+TIME(0,30,0),overlapDays,MAX(0,MIN(endDT,intervalEnd)-MAX(startDT,intervalStart)),IF(OR(id="",code="",rawStart="",rawEnd="",rawStart=rawEnd,countsAsStaffed=0),0,overlapDays/TIME(0,30,0))) | K11: =LET(id,Schedule_Matrix!$A11,code,UPPER(TRIM(Schedule_Matrix!$D11)),rawStart,Schedule_Matrix!$F11,rawEnd,Schedule_Matrix!$G11,countsAsStaffed,IFERROR(--XLOOKUP(code,UPPER(tblActivityCodes[Code]),tblActivityCodes[CountsAsStaffed],0),0),startDT,IF(INT(rawStart)>0,rawStart,SelectedDate+MOD(rawStart,1)),endBase,IF(INT(rawEnd)>0,rawEnd,SelectedDate+MOD(rawEnd,1)),endDT,IF(endBase<=startDT,endBase+1,endBase),intervalStart,SelectedDate+Schedule_Matrix!K$1,intervalEnd,intervalStart+TIME(0,30,0),overlapDays,MAX(0,MIN(endDT,intervalEnd)-MAX(startDT,intervalStart)),IF(OR(id="",code="",rawStart="",rawEnd="",rawStart=rawEnd,countsAsStaffed=0),0,overlapDays/TIME(0,30,0))) | L11: =LET(id,Schedule_Matrix!$A11,code,UPPER(TRIM(Schedule_Matrix!$D11)),rawStart,Schedule_Matrix!$F11,rawEnd,Schedule_Matrix!$G11,countsAsStaffed,IFERROR(--XLOOKUP(code,UPPER(tblActivityCodes[Code]),tblActivityCodes[CountsAsStaffed],0),0),startDT,IF(INT(rawStart)>0,rawStart,SelectedDate+MOD(rawStart,1)),endBase,IF(INT(rawEnd)>0,rawEnd,SelectedDate+MOD(rawEnd,1)),endDT,IF(endBase<=startDT,endBase+1,endBase),intervalStart,SelectedDate+Schedule_Matrix!L$1,intervalEnd,intervalStart+TIME(0,30,0),overlapDays,MAX(0,MIN(endDT,intervalEnd)-MAX(startDT,intervalStart)),IF(OR(id="",code="",rawStart="",rawEnd="",rawStart=rawEnd,countsAsStaffed=0),0,overlapDays/TIME(0,30,0))) | M11: =LET(id,Schedule_Matrix!$A11,code,UPPER(TRIM(Schedule_Matrix!$D11)),rawStart,Schedule_Matrix!$F11,rawEnd,Schedule_Matrix!$G11,countsAsStaffed,IFERROR(--XLOOKUP(code,UPPER(tblActivityCodes[Code]),tblActivityCodes[CountsAsStaffed],0),0),startDT,IF(INT(rawStart)>0,rawStart,SelectedDate+MOD(rawStart,1)),endBase,IF(INT(rawEnd)>0,rawEnd,SelectedDate+MOD(rawEnd,1)),endDT,IF(endBase<=startDT,endBase+1,endBase),intervalStart,SelectedDate+Schedule_Matrix!M$1,intervalEnd,intervalStart+TIME(0,30,0),overlapDays,MAX(0,MIN(endDT,intervalEnd)-MAX(startDT,intervalStart)),IF(OR(id="",code="",rawStart="",rawEnd="",rawStart=rawEnd,countsAsStaffed=0),0,overlapDays/TIME(0,30,0))) | N11: =LET(id,Schedule_Matrix!$A11,code,UPPER(TRIM(Schedule_Matrix!$D11)),rawStart,Schedule_Matrix!$F11,rawEnd,Schedule_Matrix!$G11,countsAsStaffed,IFERROR(--XLOOKUP(code,UPPER(tblActivityCodes[Code]),tblActivityCodes[CountsAsStaffed],0),0),startDT,IF(INT(rawStart)>0,rawStart,SelectedDate+MOD(rawStart,1)),endBase,IF(INT(rawEnd)>0,rawEnd,SelectedDate+MOD(rawEnd,1)),endDT,IF(endBase<=startDT,endBase+1,endBase),intervalStart,SelectedDate+Schedule_Matrix!N$1,intervalEnd,intervalStart+TIME(0,30,0),overlapDays,MAX(0,MIN(endDT,intervalEnd)-MAX(startDT,intervalStart)),IF(OR(id="",code="",rawStart="",rawEnd="",rawStart=rawEnd,countsAsStaffed=0),0,overlapDays/TIME(0,30,0))) | O11: =LET(id,Schedule_Matrix!$A11,code,UPPER(TRIM(Schedule_Matrix!$D11)),rawStart,Schedule_Matrix!$F11,rawEnd,Schedule_Matrix!$G11,countsAsStaffed,IFERROR(--XLOOKUP(code,UPPER(tblActivityCodes[Code]),tblActivityCodes[CountsAsStaffed],0),0),startDT,IF(INT(rawStart)>0,rawStart,SelectedDate+MOD(rawStart,1)),endBase,IF(INT(rawEnd)>0,rawEnd,SelectedDate+MOD(rawEnd,1)),endDT,IF(endBase<=startDT,endBase+1,endBase),intervalStart,SelectedDate+Schedule_Matrix!O$1,intervalEnd,intervalStart+TIME(0,30,0),overlapDays,MAX(0,MIN(endDT,intervalEnd)-MAX(startDT,intervalStart)),IF(OR(id="",code="",rawStart="",rawEnd="",rawStart=rawEnd,countsAsStaffed=0),0,overlapDays/TIME(0,30,0))) | ... BC11: =LET(id,Schedule_Matrix!$A11,code,UPPER(TRIM(Schedule_Matrix!$D11)),rawStart,Schedule_Matrix!$F11,rawEnd,Schedule_Matrix!$G11,countsAsStaffed,IFERROR(--XLOOKUP(code,UPPER(tblActivityCodes[Code]),tblActivityCodes[CountsAsStaffed],0),0),startDT,IF(INT(rawStart)>0,rawStart,SelectedDate+MOD(rawStart,1)),endBase,IF(INT(rawEnd)>0,rawEnd,SelectedDate+MOD(rawEnd,1)),endDT,IF(endBase<=startDT,endBase+1,endBase),intervalStart,SelectedDate+Schedule_Matrix!BC$1,intervalEnd,intervalStart+TIME(0,30,0),overlapDays,MAX(0,MIN(endDT,intervalEnd)-MAX(startDT,intervalStart)),IF(OR(id="",code="",rawStart="",rawEnd="",rawStart=rawEnd,countsAsStaffed=0),0,overlapDays/TIME(0,30,0)))
H12: =LET(id,Schedule_Matrix!$A12,code,UPPER(TRIM(Schedule_Matrix!$D12)),rawStart,Schedule_Matrix!$F12,rawEnd,Schedule_Matrix!$G12,countsAsStaffed,IFERROR(--XLOOKUP(code,UPPER(tblActivityCodes[Code]),tblActivityCodes[CountsAsStaffed],0),0),startDT,IF(INT(rawStart)>0,rawStart,SelectedDate+MOD(rawStart,1)),endBase,IF(INT(rawEnd)>0,rawEnd,SelectedDate+MOD(rawEnd,1)),endDT,IF(endBase<=startDT,endBase+1,endBase),intervalStart,SelectedDate+Schedule_Matrix!H$1,intervalEnd,intervalStart+TIME(0,30,0),overlapDays,MAX(0,MIN(endDT,intervalEnd)-MAX(startDT,intervalStart)),IF(OR(id="",code="",rawStart="",rawEnd="",rawStart=rawEnd,countsAsStaffed=0),0,overlapDays/TIME(0,30,0))) | I12: =LET(id,Schedule_Matrix!$A12,code,UPPER(TRIM(Schedule_Matrix!$D12)),rawStart,Schedule_Matrix!$F12,rawEnd,Schedule_Matrix!$G12,countsAsStaffed,IFERROR(--XLOOKUP(code,UPPER(tblActivityCodes[Code]),tblActivityCodes[CountsAsStaffed],0),0),startDT,IF(INT(rawStart)>0,rawStart,SelectedDate+MOD(rawStart,1)),endBase,IF(INT(rawEnd)>0,rawEnd,SelectedDate+MOD(rawEnd,1)),endDT,IF(endBase<=startDT,endBase+1,endBase),intervalStart,SelectedDate+Schedule_Matrix!I$1,intervalEnd,intervalStart+TIME(0,30,0),overlapDays,MAX(0,MIN(endDT,intervalEnd)-MAX(startDT,intervalStart)),IF(OR(id="",code="",rawStart="",rawEnd="",rawStart=rawEnd,countsAsStaffed=0),0,overlapDays/TIME(0,30,0))) | J12: =LET(id,Schedule_Matrix!$A12,code,UPPER(TRIM(Schedule_Matrix!$D12)),rawStart,Schedule_Matrix!$F12,rawEnd,Schedule_Matrix!$G12,countsAsStaffed,IFERROR(--XLOOKUP(code,UPPER(tblActivityCodes[Code]),tblActivityCodes[CountsAsStaffed],0),0),startDT,IF(INT(rawStart)>0,rawStart,SelectedDate+MOD(rawStart,1)),endBase,IF(INT(rawEnd)>0,rawEnd,SelectedDate+MOD(rawEnd,1)),endDT,IF(endBase<=startDT,endBase+1,endBase),intervalStart,SelectedDate+Schedule_Matrix!J$1,intervalEnd,intervalStart+TIME(0,30,0),overlapDays,MAX(0,MIN(endDT,intervalEnd)-MAX(startDT,intervalStart)),IF(OR(id="",code="",rawStart="",rawEnd="",rawStart=rawEnd,countsAsStaffed=0),0,overlapDays/TIME(0,30,0))) | K12: =LET(id,Schedule_Matrix!$A12,code,UPPER(TRIM(Schedule_Matrix!$D12)),rawStart,Schedule_Matrix!$F12,rawEnd,Schedule_Matrix!$G12,countsAsStaffed,IFERROR(--XLOOKUP(code,UPPER(tblActivityCodes[Code]),tblActivityCodes[CountsAsStaffed],0),0),startDT,IF(INT(rawStart)>0,rawStart,SelectedDate+MOD(rawStart,1)),endBase,IF(INT(rawEnd)>0,rawEnd,SelectedDate+MOD(rawEnd,1)),endDT,IF(endBase<=startDT,endBase+1,endBase),intervalStart,SelectedDate+Schedule_Matrix!K$1,intervalEnd,intervalStart+TIME(0,30,0),overlapDays,MAX(0,MIN(endDT,intervalEnd)-MAX(startDT,intervalStart)),IF(OR(id="",code="",rawStart="",rawEnd="",rawStart=rawEnd,countsAsStaffed=0),0,overlapDays/TIME(0,30,0))) | L12: =LET(id,Schedule_Matrix!$A12,code,UPPER(TRIM(Schedule_Matrix!$D12)),rawStart,Schedule_Matrix!$F12,rawEnd,Schedule_Matrix!$G12,countsAsStaffed,IFERROR(--XLOOKUP(code,UPPER(tblActivityCodes[Code]),tblActivityCodes[CountsAsStaffed],0),0),startDT,IF(INT(rawStart)>0,rawStart,SelectedDate+MOD(rawStart,1)),endBase,IF(INT(rawEnd)>0,rawEnd,SelectedDate+MOD(rawEnd,1)),endDT,IF(endBase<=startDT,endBase+1,endBase),intervalStart,SelectedDate+Schedule_Matrix!L$1,intervalEnd,intervalStart+TIME(0,30,0),overlapDays,MAX(0,MIN(endDT,intervalEnd)-MAX(startDT,intervalStart)),IF(OR(id="",code="",rawStart="",rawEnd="",rawStart=rawEnd,countsAsStaffed=0),0,overlapDays/TIME(0,30,0))) | M12: =LET(id,Schedule_Matrix!$A12,code,UPPER(TRIM(Schedule_Matrix!$D12)),rawStart,Schedule_Matrix!$F12,rawEnd,Schedule_Matrix!$G12,countsAsStaffed,IFERROR(--XLOOKUP(code,UPPER(tblActivityCodes[Code]),tblActivityCodes[CountsAsStaffed],0),0),startDT,IF(INT(rawStart)>0,rawStart,SelectedDate+MOD(rawStart,1)),endBase,IF(INT(rawEnd)>0,rawEnd,SelectedDate+MOD(rawEnd,1)),endDT,IF(endBase<=startDT,endBase+1,endBase),intervalStart,SelectedDate+Schedule_Matrix!M$1,intervalEnd,intervalStart+TIME(0,30,0),overlapDays,MAX(0,MIN(endDT,intervalEnd)-MAX(startDT,intervalStart)),IF(OR(id="",code="",rawStart="",rawEnd="",rawStart=rawEnd,countsAsStaffed=0),0,overlapDays/TIME(0,30,0))) | N12: =LET(id,Schedule_Matrix!$A12,code,UPPER(TRIM(Schedule_Matrix!$D12)),rawStart,Schedule_Matrix!$F12,rawEnd,Schedule_Matrix!$G12,countsAsStaffed,IFERROR(--XLOOKUP(code,UPPER(tblActivityCodes[Code]),tblActivityCodes[CountsAsStaffed],0),0),startDT,IF(INT(rawStart)>0,rawStart,SelectedDate+MOD(rawStart,1)),endBase,IF(INT(rawEnd)>0,rawEnd,SelectedDate+MOD(rawEnd,1)),endDT,IF(endBase<=startDT,endBase+1,endBase),intervalStart,SelectedDate+Schedule_Matrix!N$1,intervalEnd,intervalStart+TIME(0,30,0),overlapDays,MAX(0,MIN(endDT,intervalEnd)-MAX(startDT,intervalStart)),IF(OR(id="",code="",rawStart="",rawEnd="",rawStart=rawEnd,countsAsStaffed=0),0,overlapDays/TIME(0,30,0))) | O12: =LET(id,Schedule_Matrix!$A12,code,UPPER(TRIM(Schedule_Matrix!$D12)),rawStart,Schedule_Matrix!$F12,rawEnd,Schedule_Matrix!$G12,countsAsStaffed,IFERROR(--XLOOKUP(code,UPPER(tblActivityCodes[Code]),tblActivityCodes[CountsAsStaffed],0),0),startDT,IF(INT(rawStart)>0,rawStart,SelectedDate+MOD(rawStart,1)),endBase,IF(INT(rawEnd)>0,rawEnd,SelectedDate+MOD(rawEnd,1)),endDT,IF(endBase<=startDT,endBase+1,endBase),intervalStart,SelectedDate+Schedule_Matrix!O$1,intervalEnd,intervalStart+TIME(0,30,0),overlapDays,MAX(0,MIN(endDT,intervalEnd)-MAX(startDT,intervalStart)),IF(OR(id="",code="",rawStart="",rawEnd="",rawStart=rawEnd,countsAsStaffed=0),0,overlapDays/TIME(0,30,0))) | ... BC12: =LET(id,Schedule_Matrix!$A12,code,UPPER(TRIM(Schedule_Matrix!$D12)),rawStart,Schedule_Matrix!$F12,rawEnd,Schedule_Matrix!$G12,countsAsStaffed,IFERROR(--XLOOKUP(code,UPPER(tblActivityCodes[Code]),tblActivityCodes[CountsAsStaffed],0),0),startDT,IF(INT(rawStart)>0,rawStart,SelectedDate+MOD(rawStart,1)),endBase,IF(INT(rawEnd)>0,rawEnd,SelectedDate+MOD(rawEnd,1)),endDT,IF(endBase<=startDT,endBase+1,endBase),intervalStart,SelectedDate+Schedule_Matrix!BC$1,intervalEnd,intervalStart+TIME(0,30,0),overlapDays,MAX(0,MIN(endDT,intervalEnd)-MAX(startDT,intervalStart)),IF(OR(id="",code="",rawStart="",rawEnd="",rawStart=rawEnd,countsAsStaffed=0),0,overlapDays/TIME(0,30,0)))
H13: =LET(id,Schedule_Matrix!$A13,code,UPPER(TRIM(Schedule_Matrix!$D13)),rawStart,Schedule_Matrix!$F13,rawEnd,Schedule_Matrix!$G13,countsAsStaffed,IFERROR(--XLOOKUP(code,UPPER(tblActivityCodes[Code]),tblActivityCodes[CountsAsStaffed],0),0),startDT,IF(INT(rawStart)>0,rawStart,SelectedDate+MOD(rawStart,1)),endBase,IF(INT(rawEnd)>0,rawEnd,SelectedDate+MOD(rawEnd,1)),endDT,IF(endBase<=startDT,endBase+1,endBase),intervalStart,SelectedDate+Schedule_Matrix!H$1,intervalEnd,intervalStart+TIME(0,30,0),overlapDays,MAX(0,MIN(endDT,intervalEnd)-MAX(startDT,intervalStart)),IF(OR(id="",code="",rawStart="",rawEnd="",rawStart=rawEnd,countsAsStaffed=0),0,overlapDays/TIME(0,30,0))) | I13: =LET(id,Schedule_Matrix!$A13,code,UPPER(TRIM(Schedule_Matrix!$D13)),rawStart,Schedule_Matrix!$F13,rawEnd,Schedule_Matrix!$G13,countsAsStaffed,IFERROR(--XLOOKUP(code,UPPER(tblActivityCodes[Code]),tblActivityCodes[CountsAsStaffed],0),0),startDT,IF(INT(rawStart)>0,rawStart,SelectedDate+MOD(rawStart,1)),endBase,IF(INT(rawEnd)>0,rawEnd,SelectedDate+MOD(rawEnd,1)),endDT,IF(endBase<=startDT,endBase+1,endBase),intervalStart,SelectedDate+Schedule_Matrix!I$1,intervalEnd,intervalStart+TIME(0,30,0),overlapDays,MAX(0,MIN(endDT,intervalEnd)-MAX(startDT,intervalStart)),IF(OR(id="",code="",rawStart="",rawEnd="",rawStart=rawEnd,countsAsStaffed=0),0,overlapDays/TIME(0,30,0))) | J13: =LET(id,Schedule_Matrix!$A13,code,UPPER(TRIM(Schedule_Matrix!$D13)),rawStart,Schedule_Matrix!$F13,rawEnd,Schedule_Matrix!$G13,countsAsStaffed,IFERROR(--XLOOKUP(code,UPPER(tblActivityCodes[Code]),tblActivityCodes[CountsAsStaffed],0),0),startDT,IF(INT(rawStart)>0,rawStart,SelectedDate+MOD(rawStart,1)),endBase,IF(INT(rawEnd)>0,rawEnd,SelectedDate+MOD(rawEnd,1)),endDT,IF(endBase<=startDT,endBase+1,endBase),intervalStart,SelectedDate+Schedule_Matrix!J$1,intervalEnd,intervalStart+TIME(0,30,0),overlapDays,MAX(0,MIN(endDT,intervalEnd)-MAX(startDT,intervalStart)),IF(OR(id="",code="",rawStart="",rawEnd="",rawStart=rawEnd,countsAsStaffed=0),0,overlapDays/TIME(0,30,0))) | K13: =LET(id,Schedule_Matrix!$A13,code,UPPER(TRIM(Schedule_Matrix!$D13)),rawStart,Schedule_Matrix!$F13,rawEnd,Schedule_Matrix!$G13,countsAsStaffed,IFERROR(--XLOOKUP(code,UPPER(tblActivityCodes[Code]),tblActivityCodes[CountsAsStaffed],0),0),startDT,IF(INT(rawStart)>0,rawStart,SelectedDate+MOD(rawStart,1)),endBase,IF(INT(rawEnd)>0,rawEnd,SelectedDate+MOD(rawEnd,1)),endDT,IF(endBase<=startDT,endBase+1,endBase),intervalStart,SelectedDate+Schedule_Matrix!K$1,intervalEnd,intervalStart+TIME(0,30,0),overlapDays,MAX(0,MIN(endDT,intervalEnd)-MAX(startDT,intervalStart)),IF(OR(id="",code="",rawStart="",rawEnd="",rawStart=rawEnd,countsAsStaffed=0),0,overlapDays/TIME(0,30,0))) | L13: =LET(id,Schedule_Matrix!$A13,code,UPPER(TRIM(Schedule_Matrix!$D13)),rawStart,Schedule_Matrix!$F13,rawEnd,Schedule_Matrix!$G13,countsAsStaffed,IFERROR(--XLOOKUP(code,UPPER(tblActivityCodes[Code]),tblActivityCodes[CountsAsStaffed],0),0),startDT,IF(INT(rawStart)>0,rawStart,SelectedDate+MOD(rawStart,1)),endBase,IF(INT(rawEnd)>0,rawEnd,SelectedDate+MOD(rawEnd,1)),endDT,IF(endBase<=startDT,endBase+1,endBase),intervalStart,SelectedDate+Schedule_Matrix!L$1,intervalEnd,intervalStart+TIME(0,30,0),overlapDays,MAX(0,MIN(endDT,intervalEnd)-MAX(startDT,intervalStart)),IF(OR(id="",code="",rawStart="",rawEnd="",rawStart=rawEnd,countsAsStaffed=0),0,overlapDays/TIME(0,30,0))) | M13: =LET(id,Schedule_Matrix!$A13,code,UPPER(TRIM(Schedule_Matrix!$D13)),rawStart,Schedule_Matrix!$F13,rawEnd,Schedule_Matrix!$G13,countsAsStaffed,IFERROR(--XLOOKUP(code,UPPER(tblActivityCodes[Code]),tblActivityCodes[CountsAsStaffed],0),0),startDT,IF(INT(rawStart)>0,rawStart,SelectedDate+MOD(rawStart,1)),endBase,IF(INT(rawEnd)>0,rawEnd,SelectedDate+MOD(rawEnd,1)),endDT,IF(endBase<=startDT,endBase+1,endBase),intervalStart,SelectedDate+Schedule_Matrix!M$1,intervalEnd,intervalStart+TIME(0,30,0),overlapDays,MAX(0,MIN(endDT,intervalEnd)-MAX(startDT,intervalStart)),IF(OR(id="",code="",rawStart="",rawEnd="",rawStart=rawEnd,countsAsStaffed=0),0,overlapDays/TIME(0,30,0))) | N13: =LET(id,Schedule_Matrix!$A13,code,UPPER(TRIM(Schedule_Matrix!$D13)),rawStart,Schedule_Matrix!$F13,rawEnd,Schedule_Matrix!$G13,countsAsStaffed,IFERROR(--XLOOKUP(code,UPPER(tblActivityCodes[Code]),tblActivityCodes[CountsAsStaffed],0),0),startDT,IF(INT(rawStart)>0,rawStart,SelectedDate+MOD(rawStart,1)),endBase,IF(INT(rawEnd)>0,rawEnd,SelectedDate+MOD(rawEnd,1)),endDT,IF(endBase<=startDT,endBase+1,endBase),intervalStart,SelectedDate+Schedule_Matrix!N$1,intervalEnd,intervalStart+TIME(0,30,0),overlapDays,MAX(0,MIN(endDT,intervalEnd)-MAX(startDT,intervalStart)),IF(OR(id="",code="",rawStart="",rawEnd="",rawStart=rawEnd,countsAsStaffed=0),0,overlapDays/TIME(0,30,0))) | O13: =LET(id,Schedule_Matrix!$A13,code,UPPER(TRIM(Schedule_Matrix!$D13)),rawStart,Schedule_Matrix!$F13,rawEnd,Schedule_Matrix!$G13,countsAsStaffed,IFERROR(--XLOOKUP(code,UPPER(tblActivityCodes[Code]),tblActivityCodes[CountsAsStaffed],0),0),startDT,IF(INT(rawStart)>0,rawStart,SelectedDate+MOD(rawStart,1)),endBase,IF(INT(rawEnd)>0,rawEnd,SelectedDate+MOD(rawEnd,1)),endDT,IF(endBase<=startDT,endBase+1,endBase),intervalStart,SelectedDate+Schedule_Matrix!O$1,intervalEnd,intervalStart+TIME(0,30,0),overlapDays,MAX(0,MIN(endDT,intervalEnd)-MAX(startDT,intervalStart)),IF(OR(id="",code="",rawStart="",rawEnd="",rawStart=rawEnd,countsAsStaffed=0),0,overlapDays/TIME(0,30,0))) | ... BC13: =LET(id,Schedule_Matrix!$A13,code,UPPER(TRIM(Schedule_Matrix!$D13)),rawStart,Schedule_Matrix!$F13,rawEnd,Schedule_Matrix!$G13,countsAsStaffed,IFERROR(--XLOOKUP(code,UPPER(tblActivityCodes[Code]),tblActivityCodes[CountsAsStaffed],0),0),startDT,IF(INT(rawStart)>0,rawStart,SelectedDate+MOD(rawStart,1)),endBase,IF(INT(rawEnd)>0,rawEnd,SelectedDate+MOD(rawEnd,1)),endDT,IF(endBase<=startDT,endBase+1,endBase),intervalStart,SelectedDate+Schedule_Matrix!BC$1,intervalEnd,intervalStart+TIME(0,30,0),overlapDays,MAX(0,MIN(endDT,intervalEnd)-MAX(startDT,intervalStart)),IF(OR(id="",code="",rawStart="",rawEnd="",rawStart=rawEnd,countsAsStaffed=0),0,overlapDays/TIME(0,30,0)))
H14: =LET(id,Schedule_Matrix!$A14,code,UPPER(TRIM(Schedule_Matrix!$D14)),rawStart,Schedule_Matrix!$F14,rawEnd,Schedule_Matrix!$G14,countsAsStaffed,IFERROR(--XLOOKUP(code,UPPER(tblActivityCodes[Code]),tblActivityCodes[CountsAsStaffed],0),0),startDT,IF(INT(rawStart)>0,rawStart,SelectedDate+MOD(rawStart,1)),endBase,IF(INT(rawEnd)>0,rawEnd,SelectedDate+MOD(rawEnd,1)),endDT,IF(endBase<=startDT,endBase+1,endBase),intervalStart,SelectedDate+Schedule_Matrix!H$1,intervalEnd,intervalStart+TIME(0,30,0),overlapDays,MAX(0,MIN(endDT,intervalEnd)-MAX(startDT,intervalStart)),IF(OR(id="",code="",rawStart="",rawEnd="",rawStart=rawEnd,countsAsStaffed=0),0,overlapDays/TIME(0,30,0))) | I14: =LET(id,Schedule_Matrix!$A14,code,UPPER(TRIM(Schedule_Matrix!$D14)),rawStart,Schedule_Matrix!$F14,rawEnd,Schedule_Matrix!$G14,countsAsStaffed,IFERROR(--XLOOKUP(code,UPPER(tblActivityCodes[Code]),tblActivityCodes[CountsAsStaffed],0),0),startDT,IF(INT(rawStart)>0,rawStart,SelectedDate+MOD(rawStart,1)),endBase,IF(INT(rawEnd)>0,rawEnd,SelectedDate+MOD(rawEnd,1)),endDT,IF(endBase<=startDT,endBase+1,endBase),intervalStart,SelectedDate+Schedule_Matrix!I$1,intervalEnd,intervalStart+TIME(0,30,0),overlapDays,MAX(0,MIN(endDT,intervalEnd)-MAX(startDT,intervalStart)),IF(OR(id="",code="",rawStart="",rawEnd="",rawStart=rawEnd,countsAsStaffed=0),0,overlapDays/TIME(0,30,0))) | J14: =LET(id,Schedule_Matrix!$A14,code,UPPER(TRIM(Schedule_Matrix!$D14)),rawStart,Schedule_Matrix!$F14,rawEnd,Schedule_Matrix!$G14,countsAsStaffed,IFERROR(--XLOOKUP(code,UPPER(tblActivityCodes[Code]),tblActivityCodes[CountsAsStaffed],0),0),startDT,IF(INT(rawStart)>0,rawStart,SelectedDate+MOD(rawStart,1)),endBase,IF(INT(rawEnd)>0,rawEnd,SelectedDate+MOD(rawEnd,1)),endDT,IF(endBase<=startDT,endBase+1,endBase),intervalStart,SelectedDate+Schedule_Matrix!J$1,intervalEnd,intervalStart+TIME(0,30,0),overlapDays,MAX(0,MIN(endDT,intervalEnd)-MAX(startDT,intervalStart)),IF(OR(id="",code="",rawStart="",rawEnd="",rawStart=rawEnd,countsAsStaffed=0),0,overlapDays/TIME(0,30,0))) | K14: =LET(id,Schedule_Matrix!$A14,code,UPPER(TRIM(Schedule_Matrix!$D14)),rawStart,Schedule_Matrix!$F14,rawEnd,Schedule_Matrix!$G14,countsAsStaffed,IFERROR(--XLOOKUP(code,UPPER(tblActivityCodes[Code]),tblActivityCodes[CountsAsStaffed],0),0),startDT,IF(INT(rawStart)>0,rawStart,SelectedDate+MOD(rawStart,1)),endBase,IF(INT(rawEnd)>0,rawEnd,SelectedDate+MOD(rawEnd,1)),endDT,IF(endBase<=startDT,endBase+1,endBase),intervalStart,SelectedDate+Schedule_Matrix!K$1,intervalEnd,intervalStart+TIME(0,30,0),overlapDays,MAX(0,MIN(endDT,intervalEnd)-MAX(startDT,intervalStart)),IF(OR(id="",code="",rawStart="",rawEnd="",rawStart=rawEnd,countsAsStaffed=0),0,overlapDays/TIME(0,30,0))) | L14: =LET(id,Schedule_Matrix!$A14,code,UPPER(TRIM(Schedule_Matrix!$D14)),rawStart,Schedule_Matrix!$F14,rawEnd,Schedule_Matrix!$G14,countsAsStaffed,IFERROR(--XLOOKUP(code,UPPER(tblActivityCodes[Code]),tblActivityCodes[CountsAsStaffed],0),0),startDT,IF(INT(rawStart)>0,rawStart,SelectedDate+MOD(rawStart,1)),endBase,IF(INT(rawEnd)>0,rawEnd,SelectedDate+MOD(rawEnd,1)),endDT,IF(endBase<=startDT,endBase+1,endBase),intervalStart,SelectedDate+Schedule_Matrix!L$1,intervalEnd,intervalStart+TIME(0,30,0),overlapDays,MAX(0,MIN(endDT,intervalEnd)-MAX(startDT,intervalStart)),IF(OR(id="",code="",rawStart="",rawEnd="",rawStart=rawEnd,countsAsStaffed=0),0,overlapDays/TIME(0,30,0))) | M14: =LET(id,Schedule_Matrix!$A14,code,UPPER(TRIM(Schedule_Matrix!$D14)),rawStart,Schedule_Matrix!$F14,rawEnd,Schedule_Matrix!$G14,countsAsStaffed,IFERROR(--XLOOKUP(code,UPPER(tblActivityCodes[Code]),tblActivityCodes[CountsAsStaffed],0),0),startDT,IF(INT(rawStart)>0,rawStart,SelectedDate+MOD(rawStart,1)),endBase,IF(INT(rawEnd)>0,rawEnd,SelectedDate+MOD(rawEnd,1)),endDT,IF(endBase<=startDT,endBase+1,endBase),intervalStart,SelectedDate+Schedule_Matrix!M$1,intervalEnd,intervalStart+TIME(0,30,0),overlapDays,MAX(0,MIN(endDT,intervalEnd)-MAX(startDT,intervalStart)),IF(OR(id="",code="",rawStart="",rawEnd="",rawStart=rawEnd,countsAsStaffed=0),0,overlapDays/TIME(0,30,0))) | N14: =LET(id,Schedule_Matrix!$A14,code,UPPER(TRIM(Schedule_Matrix!$D14)),rawStart,Schedule_Matrix!$F14,rawEnd,Schedule_Matrix!$G14,countsAsStaffed,IFERROR(--XLOOKUP(code,UPPER(tblActivityCodes[Code]),tblActivityCodes[CountsAsStaffed],0),0),startDT,IF(INT(rawStart)>0,rawStart,SelectedDate+MOD(rawStart,1)),endBase,IF(INT(rawEnd)>0,rawEnd,SelectedDate+MOD(rawEnd,1)),endDT,IF(endBase<=startDT,endBase+1,endBase),intervalStart,SelectedDate+Schedule_Matrix!N$1,intervalEnd,intervalStart+TIME(0,30,0),overlapDays,MAX(0,MIN(endDT,intervalEnd)-MAX(startDT,intervalStart)),IF(OR(id="",code="",rawStart="",rawEnd="",rawStart=rawEnd,countsAsStaffed=0),0,overlapDays/TIME(0,30,0))) | O14: =LET(id,Schedule_Matrix!$A14,code,UPPER(TRIM(Schedule_Matrix!$D14)),rawStart,Schedule_Matrix!$F14,rawEnd,Schedule_Matrix!$G14,countsAsStaffed,IFERROR(--XLOOKUP(code,UPPER(tblActivityCodes[Code]),tblActivityCodes[CountsAsStaffed],0),0),startDT,IF(INT(rawStart)>0,rawStart,SelectedDate+MOD(rawStart,1)),endBase,IF(INT(rawEnd)>0,rawEnd,SelectedDate+MOD(rawEnd,1)),endDT,IF(endBase<=startDT,endBase+1,endBase),intervalStart,SelectedDate+Schedule_Matrix!O$1,intervalEnd,intervalStart+TIME(0,30,0),overlapDays,MAX(0,MIN(endDT,intervalEnd)-MAX(startDT,intervalStart)),IF(OR(id="",code="",rawStart="",rawEnd="",rawStart=rawEnd,countsAsStaffed=0),0,overlapDays/TIME(0,30,0))) | ... BC14: =LET(id,Schedule_Matrix!$A14,code,UPPER(TRIM(Schedule_Matrix!$D14)),rawStart,Schedule_Matrix!$F14,rawEnd,Schedule_Matrix!$G14,countsAsStaffed,IFERROR(--XLOOKUP(code,UPPER(tblActivityCodes[Code]),tblActivityCodes[CountsAsStaffed],0),0),startDT,IF(INT(rawStart)>0,rawStart,SelectedDate+MOD(rawStart,1)),endBase,IF(INT(rawEnd)>0,rawEnd,SelectedDate+MOD(rawEnd,1)),endDT,IF(endBase<=startDT,endBase+1,endBase),intervalStart,SelectedDate+Schedule_Matrix!BC$1,intervalEnd,intervalStart+TIME(0,30,0),overlapDays,MAX(0,MIN(endDT,intervalEnd)-MAX(startDT,intervalStart)),IF(OR(id="",code="",rawStart="",rawEnd="",rawStart=rawEnd,countsAsStaffed=0),0,overlapDays/TIME(0,30,0)))
H15: =LET(id,Schedule_Matrix!$A15,code,UPPER(TRIM(Schedule_Matrix!$D15)),rawStart,Schedule_Matrix!$F15,rawEnd,Schedule_Matrix!$G15,countsAsStaffed,IFERROR(--XLOOKUP(code,UPPER(tblActivityCodes[Code]),tblActivityCodes[CountsAsStaffed],0),0),startDT,IF(INT(rawStart)>0,rawStart,SelectedDate+MOD(rawStart,1)),endBase,IF(INT(rawEnd)>0,rawEnd,SelectedDate+MOD(rawEnd,1)),endDT,IF(endBase<=startDT,endBase+1,endBase),intervalStart,SelectedDate+Schedule_Matrix!H$1,intervalEnd,intervalStart+TIME(0,30,0),overlapDays,MAX(0,MIN(endDT,intervalEnd)-MAX(startDT,intervalStart)),IF(OR(id="",code="",rawStart="",rawEnd="",rawStart=rawEnd,countsAsStaffed=0),0,overlapDays/TIME(0,30,0))) | I15: =LET(id,Schedule_Matrix!$A15,code,UPPER(TRIM(Schedule_Matrix!$D15)),rawStart,Schedule_Matrix!$F15,rawEnd,Schedule_Matrix!$G15,countsAsStaffed,IFERROR(--XLOOKUP(code,UPPER(tblActivityCodes[Code]),tblActivityCodes[CountsAsStaffed],0),0),startDT,IF(INT(rawStart)>0,rawStart,SelectedDate+MOD(rawStart,1)),endBase,IF(INT(rawEnd)>0,rawEnd,SelectedDate+MOD(rawEnd,1)),endDT,IF(endBase<=startDT,endBase+1,endBase),intervalStart,SelectedDate+Schedule_Matrix!I$1,intervalEnd,intervalStart+TIME(0,30,0),overlapDays,MAX(0,MIN(endDT,intervalEnd)-MAX(startDT,intervalStart)),IF(OR(id="",code="",rawStart="",rawEnd="",rawStart=rawEnd,countsAsStaffed=0),0,overlapDays/TIME(0,30,0))) | J15: =LET(id,Schedule_Matrix!$A15,code,UPPER(TRIM(Schedule_Matrix!$D15)),rawStart,Schedule_Matrix!$F15,rawEnd,Schedule_Matrix!$G15,countsAsStaffed,IFERROR(--XLOOKUP(code,UPPER(tblActivityCodes[Code]),tblActivityCodes[CountsAsStaffed],0),0),startDT,IF(INT(rawStart)>0,rawStart,SelectedDate+MOD(rawStart,1)),endBase,IF(INT(rawEnd)>0,rawEnd,SelectedDate+MOD(rawEnd,1)),endDT,IF(endBase<=startDT,endBase+1,endBase),intervalStart,SelectedDate+Schedule_Matrix!J$1,intervalEnd,intervalStart+TIME(0,30,0),overlapDays,MAX(0,MIN(endDT,intervalEnd)-MAX(startDT,intervalStart)),IF(OR(id="",code="",rawStart="",rawEnd="",rawStart=rawEnd,countsAsStaffed=0),0,overlapDays/TIME(0,30,0))) | K15: =LET(id,Schedule_Matrix!$A15,code,UPPER(TRIM(Schedule_Matrix!$D15)),rawStart,Schedule_Matrix!$F15,rawEnd,Schedule_Matrix!$G15,countsAsStaffed,IFERROR(--XLOOKUP(code,UPPER(tblActivityCodes[Code]),tblActivityCodes[CountsAsStaffed],0),0),startDT,IF(INT(rawStart)>0,rawStart,SelectedDate+MOD(rawStart,1)),endBase,IF(INT(rawEnd)>0,rawEnd,SelectedDate+MOD(rawEnd,1)),endDT,IF(endBase<=startDT,endBase+1,endBase),intervalStart,SelectedDate+Schedule_Matrix!K$1,intervalEnd,intervalStart+TIME(0,30,0),overlapDays,MAX(0,MIN(endDT,intervalEnd)-MAX(startDT,intervalStart)),IF(OR(id="",code="",rawStart="",rawEnd="",rawStart=rawEnd,countsAsStaffed=0),0,overlapDays/TIME(0,30,0))) | L15: =LET(id,Schedule_Matrix!$A15,code,UPPER(TRIM(Schedule_Matrix!$D15)),rawStart,Schedule_Matrix!$F15,rawEnd,Schedule_Matrix!$G15,countsAsStaffed,IFERROR(--XLOOKUP(code,UPPER(tblActivityCodes[Code]),tblActivityCodes[CountsAsStaffed],0),0),startDT,IF(INT(rawStart)>0,rawStart,SelectedDate+MOD(rawStart,1)),endBase,IF(INT(rawEnd)>0,rawEnd,SelectedDate+MOD(rawEnd,1)),endDT,IF(endBase<=startDT,endBase+1,endBase),intervalStart,SelectedDate+Schedule_Matrix!L$1,intervalEnd,intervalStart+TIME(0,30,0),overlapDays,MAX(0,MIN(endDT,intervalEnd)-MAX(startDT,intervalStart)),IF(OR(id="",code="",rawStart="",rawEnd="",rawStart=rawEnd,countsAsStaffed=0),0,overlapDays/TIME(0,30,0))) | M15: =LET(id,Schedule_Matrix!$A15,code,UPPER(TRIM(Schedule_Matrix!$D15)),rawStart,Schedule_Matrix!$F15,rawEnd,Schedule_Matrix!$G15,countsAsStaffed,IFERROR(--XLOOKUP(code,UPPER(tblActivityCodes[Code]),tblActivityCodes[CountsAsStaffed],0),0),startDT,IF(INT(rawStart)>0,rawStart,SelectedDate+MOD(rawStart,1)),endBase,IF(INT(rawEnd)>0,rawEnd,SelectedDate+MOD(rawEnd,1)),endDT,IF(endBase<=startDT,endBase+1,endBase),intervalStart,SelectedDate+Schedule_Matrix!M$1,intervalEnd,intervalStart+TIME(0,30,0),overlapDays,MAX(0,MIN(endDT,intervalEnd)-MAX(startDT,intervalStart)),IF(OR(id="",code="",rawStart="",rawEnd="",rawStart=rawEnd,countsAsStaffed=0),0,overlapDays/TIME(0,30,0))) | N15: =LET(id,Schedule_Matrix!$A15,code,UPPER(TRIM(Schedule_Matrix!$D15)),rawStart,Schedule_Matrix!$F15,rawEnd,Schedule_Matrix!$G15,countsAsStaffed,IFERROR(--XLOOKUP(code,UPPER(tblActivityCodes[Code]),tblActivityCodes[CountsAsStaffed],0),0),startDT,IF(INT(rawStart)>0,rawStart,SelectedDate+MOD(rawStart,1)),endBase,IF(INT(rawEnd)>0,rawEnd,SelectedDate+MOD(rawEnd,1)),endDT,IF(endBase<=startDT,endBase+1,endBase),intervalStart,SelectedDate+Schedule_Matrix!N$1,intervalEnd,intervalStart+TIME(0,30,0),overlapDays,MAX(0,MIN(endDT,intervalEnd)-MAX(startDT,intervalStart)),IF(OR(id="",code="",rawStart="",rawEnd="",rawStart=rawEnd,countsAsStaffed=0),0,overlapDays/TIME(0,30,0))) | O15: =LET(id,Schedule_Matrix!$A15,code,UPPER(TRIM(Schedule_Matrix!$D15)),rawStart,Schedule_Matrix!$F15,rawEnd,Schedule_Matrix!$G15,countsAsStaffed,IFERROR(--XLOOKUP(code,UPPER(tblActivityCodes[Code]),tblActivityCodes[CountsAsStaffed],0),0),startDT,IF(INT(rawStart)>0,rawStart,SelectedDate+MOD(rawStart,1)),endBase,IF(INT(rawEnd)>0,rawEnd,SelectedDate+MOD(rawEnd,1)),endDT,IF(endBase<=startDT,endBase+1,endBase),intervalStart,SelectedDate+Schedule_Matrix!O$1,intervalEnd,intervalStart+TIME(0,30,0),overlapDays,MAX(0,MIN(endDT,intervalEnd)-MAX(startDT,intervalStart)),IF(OR(id="",code="",rawStart="",rawEnd="",rawStart=rawEnd,countsAsStaffed=0),0,overlapDays/TIME(0,30,0))) | ... BC15: =LET(id,Schedule_Matrix!$A15,code,UPPER(TRIM(Schedule_Matrix!$D15)),rawStart,Schedule_Matrix!$F15,rawEnd,Schedule_Matrix!$G15,countsAsStaffed,IFERROR(--XLOOKUP(code,UPPER(tblActivityCodes[Code]),tblActivityCodes[CountsAsStaffed],0),0),startDT,IF(INT(rawStart)>0,rawStart,SelectedDate+MOD(rawStart,1)),endBase,IF(INT(rawEnd)>0,rawEnd,SelectedDate+MOD(rawEnd,1)),endDT,IF(endBase<=startDT,endBase+1,endBase),intervalStart,SelectedDate+Schedule_Matrix!BC$1,intervalEnd,intervalStart+TIME(0,30,0),overlapDays,MAX(0,MIN(endDT,intervalEnd)-MAX(startDT,intervalStart)),IF(OR(id="",code="",rawStart="",rawEnd="",rawStart=rawEnd,countsAsStaffed=0),0,overlapDays/TIME(0,30,0)))
H16: =LET(id,Schedule_Matrix!$A16,code,UPPER(TRIM(Schedule_Matrix!$D16)),rawStart,Schedule_Matrix!$F16,rawEnd,Schedule_Matrix!$G16,countsAsStaffed,IFERROR(--XLOOKUP(code,UPPER(tblActivityCodes[Code]),tblActivityCodes[CountsAsStaffed],0),0),startDT,IF(INT(rawStart)>0,rawStart,SelectedDate+MOD(rawStart,1)),endBase,IF(INT(rawEnd)>0,rawEnd,SelectedDate+MOD(rawEnd,1)),endDT,IF(endBase<=startDT,endBase+1,endBase),intervalStart,SelectedDate+Schedule_Matrix!H$1,intervalEnd,intervalStart+TIME(0,30,0),overlapDays,MAX(0,MIN(endDT,intervalEnd)-MAX(startDT,intervalStart)),IF(OR(id="",code="",rawStart="",rawEnd="",rawStart=rawEnd,countsAsStaffed=0),0,overlapDays/TIME(0,30,0))) | I16: =LET(id,Schedule_Matrix!$A16,code,UPPER(TRIM(Schedule_Matrix!$D16)),rawStart,Schedule_Matrix!$F16,rawEnd,Schedule_Matrix!$G16,countsAsStaffed,IFERROR(--XLOOKUP(code,UPPER(tblActivityCodes[Code]),tblActivityCodes[CountsAsStaffed],0),0),startDT,IF(INT(rawStart)>0,rawStart,SelectedDate+MOD(rawStart,1)),endBase,IF(INT(rawEnd)>0,rawEnd,SelectedDate+MOD(rawEnd,1)),endDT,IF(endBase<=startDT,endBase+1,endBase),intervalStart,SelectedDate+Schedule_Matrix!I$1,intervalEnd,intervalStart+TIME(0,30,0),overlapDays,MAX(0,MIN(endDT,intervalEnd)-MAX(startDT,intervalStart)),IF(OR(id="",code="",rawStart="",rawEnd="",rawStart=rawEnd,countsAsStaffed=0),0,overlapDays/TIME(0,30,0))) | J16: =LET(id,Schedule_Matrix!$A16,code,UPPER(TRIM(Schedule_Matrix!$D16)),rawStart,Schedule_Matrix!$F16,rawEnd,Schedule_Matrix!$G16,countsAsStaffed,IFERROR(--XLOOKUP(code,UPPER(tblActivityCodes[Code]),tblActivityCodes[CountsAsStaffed],0),0),startDT,IF(INT(rawStart)>0,rawStart,SelectedDate+MOD(rawStart,1)),endBase,IF(INT(rawEnd)>0,rawEnd,SelectedDate+MOD(rawEnd,1)),endDT,IF(endBase<=startDT,endBase+1,endBase),intervalStart,SelectedDate+Schedule_Matrix!J$1,intervalEnd,intervalStart+TIME(0,30,0),overlapDays,MAX(0,MIN(endDT,intervalEnd)-MAX(startDT,intervalStart)),IF(OR(id="",code="",rawStart="",rawEnd="",rawStart=rawEnd,countsAsStaffed=0),0,overlapDays/TIME(0,30,0))) | K16: =LET(id,Schedule_Matrix!$A16,code,UPPER(TRIM(Schedule_Matrix!$D16)),rawStart,Schedule_Matrix!$F16,rawEnd,Schedule_Matrix!$G16,countsAsStaffed,IFERROR(--XLOOKUP(code,UPPER(tblActivityCodes[Code]),tblActivityCodes[CountsAsStaffed],0),0),startDT,IF(INT(rawStart)>0,rawStart,SelectedDate+MOD(rawStart,1)),endBase,IF(INT(rawEnd)>0,rawEnd,SelectedDate+MOD(rawEnd,1)),endDT,IF(endBase<=startDT,endBase+1,endBase),intervalStart,SelectedDate+Schedule_Matrix!K$1,intervalEnd,intervalStart+TIME(0,30,0),overlapDays,MAX(0,MIN(endDT,intervalEnd)-MAX(startDT,intervalStart)),IF(OR(id="",code="",rawStart="",rawEnd="",rawStart=rawEnd,countsAsStaffed=0),0,overlapDays/TIME(0,30,0))) | L16: =LET(id,Schedule_Matrix!$A16,code,UPPER(TRIM(Schedule_Matrix!$D16)),rawStart,Schedule_Matrix!$F16,rawEnd,Schedule_Matrix!$G16,countsAsStaffed,IFERROR(--XLOOKUP(code,UPPER(tblActivityCodes[Code]),tblActivityCodes[CountsAsStaffed],0),0),startDT,IF(INT(rawStart)>0,rawStart,SelectedDate+MOD(rawStart,1)),endBase,IF(INT(rawEnd)>0,rawEnd,SelectedDate+MOD(rawEnd,1)),endDT,IF(endBase<=startDT,endBase+1,endBase),intervalStart,SelectedDate+Schedule_Matrix!L$1,intervalEnd,intervalStart+TIME(0,30,0),overlapDays,MAX(0,MIN(endDT,intervalEnd)-MAX(startDT,intervalStart)),IF(OR(id="",code="",rawStart="",rawEnd="",rawStart=rawEnd,countsAsStaffed=0),0,overlapDays/TIME(0,30,0))) | M16: =LET(id,Schedule_Matrix!$A16,code,UPPER(TRIM(Schedule_Matrix!$D16)),rawStart,Schedule_Matrix!$F16,rawEnd,Schedule_Matrix!$G16,countsAsStaffed,IFERROR(--XLOOKUP(code,UPPER(tblActivityCodes[Code]),tblActivityCodes[CountsAsStaffed],0),0),startDT,IF(INT(rawStart)>0,rawStart,SelectedDate+MOD(rawStart,1)),endBase,IF(INT(rawEnd)>0,rawEnd,SelectedDate+MOD(rawEnd,1)),endDT,IF(endBase<=startDT,endBase+1,endBase),intervalStart,SelectedDate+Schedule_Matrix!M$1,intervalEnd,intervalStart+TIME(0,30,0),overlapDays,MAX(0,MIN(endDT,intervalEnd)-MAX(startDT,intervalStart)),IF(OR(id="",code="",rawStart="",rawEnd="",rawStart=rawEnd,countsAsStaffed=0),0,overlapDays/TIME(0,30,0))) | N16: =LET(id,Schedule_Matrix!$A16,code,UPPER(TRIM(Schedule_Matrix!$D16)),rawStart,Schedule_Matrix!$F16,rawEnd,Schedule_Matrix!$G16,countsAsStaffed,IFERROR(--XLOOKUP(code,UPPER(tblActivityCodes[Code]),tblActivityCodes[CountsAsStaffed],0),0),startDT,IF(INT(rawStart)>0,rawStart,SelectedDate+MOD(rawStart,1)),endBase,IF(INT(rawEnd)>0,rawEnd,SelectedDate+MOD(rawEnd,1)),endDT,IF(endBase<=startDT,endBase+1,endBase),intervalStart,SelectedDate+Schedule_Matrix!N$1,intervalEnd,intervalStart+TIME(0,30,0),overlapDays,MAX(0,MIN(endDT,intervalEnd)-MAX(startDT,intervalStart)),IF(OR(id="",code="",rawStart="",rawEnd="",rawStart=rawEnd,countsAsStaffed=0),0,overlapDays/TIME(0,30,0))) | O16: =LET(id,Schedule_Matrix!$A16,code,UPPER(TRIM(Schedule_Matrix!$D16)),rawStart,Schedule_Matrix!$F16,rawEnd,Schedule_Matrix!$G16,countsAsStaffed,IFERROR(--XLOOKUP(code,UPPER(tblActivityCodes[Code]),tblActivityCodes[CountsAsStaffed],0),0),startDT,IF(INT(rawStart)>0,rawStart,SelectedDate+MOD(rawStart,1)),endBase,IF(INT(rawEnd)>0,rawEnd,SelectedDate+MOD(rawEnd,1)),endDT,IF(endBase<=startDT,endBase+1,endBase),intervalStart,SelectedDate+Schedule_Matrix!O$1,intervalEnd,intervalStart+TIME(0,30,0),overlapDays,MAX(0,MIN(endDT,intervalEnd)-MAX(startDT,intervalStart)),IF(OR(id="",code="",rawStart="",rawEnd="",rawStart=rawEnd,countsAsStaffed=0),0,overlapDays/TIME(0,30,0))) | ... BC16: =LET(id,Schedule_Matrix!$A16,code,UPPER(TRIM(Schedule_Matrix!$D16)),rawStart,Schedule_Matrix!$F16,rawEnd,Schedule_Matrix!$G16,countsAsStaffed,IFERROR(--XLOOKUP(code,UPPER(tblActivityCodes[Code]),tblActivityCodes[CountsAsStaffed],0),0),startDT,IF(INT(rawStart)>0,rawStart,SelectedDate+MOD(rawStart,1)),endBase,IF(INT(rawEnd)>0,rawEnd,SelectedDate+MOD(rawEnd,1)),endDT,IF(endBase<=startDT,endBase+1,endBase),intervalStart,SelectedDate+Schedule_Matrix!BC$1,intervalEnd,intervalStart+TIME(0,30,0),overlapDays,MAX(0,MIN(endDT,intervalEnd)-MAX(startDT,intervalStart)),IF(OR(id="",code="",rawStart="",rawEnd="",rawStart=rawEnd,countsAsStaffed=0),0,overlapDays/TIME(0,30,0)))
